<?xml version="1.0"?>

<robot name="myrobot" xmlns:xacro="http://www.ros.org/wiki/xacro">

 <link name="base_footprint">
</link>

<!-- <link name="odom"/> -->
  

<!-- <joint name="map_joint" type="fixed">
  <parent link="map"/>
  <child link="odom"/>

</joint> -->


<link name="base_link">
    <pose>0 0 0.1 0 0 0</pose>

       <inertial>
      <mass value="15.0"/>
      <origin xyz="0.0 0 0" rpy=" 0 0 0"/>
      <inertia
          ixx="0.1" ixy="0" ixz="0"
          iyy="0.1" iyz="0"
          izz="0.1"
      />
    </inertial>

    <collision name='collision'>
      <origin xyz="0 0 0" rpy=" 0 0 0"/> 
      <geometry>
        <cylinder radius="0.2" length="0.07"/>
      </geometry>
    </collision>

    <visual name="base_link_visual">
      <origin xyz="0 0 0" rpy=" 0 0 0"/>
      <geometry>
        <cylinder radius="0.2" length="0.07"/>
      </geometry>
      <material name="yellow">
        <color rgba="1.0 1.0 0.0 1.0"/>
        <texture filename=""/>
      </material>
    </visual>
</link>



<link name="right_wheel_link">
    <pose>0 0 0.1 0 0 0</pose>
     <inertial>
	   <mass value="3.0"/>
	     <origin xyz="0 0 0" rpy=" 0 0 0"/>
		 <inertia
		      ixx="0.1" ixy="0" ixz="0"
		      iyy="0.1" iyz="0"
		      izz="0.1"
		 />
	 </inertial>

	 <collision name=''>
	   <origin xyz="0 0 0" rpy=" 0 0 0"/>
	   <geometry>
	     <cylinder radius="0.05" length="0.03"/>
	   </geometry>
	 </collision>

	 <visual name=''>
	   <origin xyz="0 0 0" rpy=" 0 0 0"/>
	     <geometry>
		   <cylinder radius="0.05" length="0.03"/>
		 </geometry>
        <material name="red">
        <color rgba="1.0 .0 0.0 1.0"/>
        <texture filename=""/>
      </material>
	 </visual>
</link>

<link name="back_wheel_link">
      <pose>0 0 0.1 0 0 0</pose>
     <inertial>
	   <mass value="3.0"/>
	     <origin xyz="0 0 0" rpy=" 0 0 0"/>
		 <inertia
		      ixx="0.1" ixy="0" ixz="0"
		      iyy="0.1" iyz="0"
		      izz="0.1"
		 />
	 </inertial>

	 <collision name=''>
	   <origin xyz="0 0 0" rpy=" 0 0 0"/>
	   <geometry>
	     <cylinder radius="0.05" length="0.03"/>
	   </geometry>
	 </collision>

	 <visual name='wight'>
	   <origin xyz="0 0 0" rpy=" 0 0 0"/>
	     <geometry>
		   <cylinder radius="0.05" length="0.03"/>
		 </geometry>
        <material name="">
        <color rgba="1.0 1.0 1.0 1.0"/>
        <texture filename=""/>
      </material>
	 </visual>
</link>

<link name="left_wheel_link">
      <pose>0 0 0.1 0 0 0</pose>
     <inertial>
	   <mass value="3.0"/>
	     <origin xyz="0 0 0" rpy=" 0 0 0"/>
		 <inertia
		      ixx="0.1" ixy="0" ixz="0"
		      iyy="0.1" iyz="0"
		      izz="0.1"
		 />
	 </inertial>

	 <collision name=''>
	   <origin xyz="0 0 0" rpy=" 0 0 0"/>
	   <geometry>
	     <cylinder radius="0.05" length="0.03"/>
	   </geometry>
	 </collision>

	 <visual name='perple'>
	   <origin xyz="0 0 0" rpy=" 0 0 0"/>
	     <geometry>
		   <cylinder radius="0.05" length="0.03"/>
		 </geometry>
        <material name="">
        <color rgba="1.0 .0 1.0 1.0"/>
        <texture filename=""/>
      </material>
	 </visual>
</link>
<link name="Imu_link">
      <pose>0 0 0.1 0 0 0</pose>
     <inertial>
	   <mass value="3.0"/>
	     <origin xyz="0 0 0" rpy=" 0 0 0"/>
		 <inertia
		      ixx="0.1" ixy="0" ixz="0"
		      iyy="0.1" iyz="0"
		      izz="0.1"
		 />
	 </inertial>

	 <collision name=''>
	   <origin xyz="0 0 0" rpy=" 0 0 0"/>
	   <geometry>
	     <box size="0.08 0.08 0.08"/>
	   </geometry>
	 </collision>

	 <visual name='red'>
	   <origin xyz="0 0 0.0" rpy=" 0 0 0"/>
	     <geometry>
		    <box size="0.08 0.08 0.08"/>
		 </geometry>
        <material name="">
        <color rgba="1.0 .0 0.0 1.0"/>
        <texture filename=""/>
      </material>
	 </visual>
</link>

<!-- <joint name="odom_joint" type="fixed">
  <origin xyz="0.0 0.0 0.0" rpy="0.0 0.0 0.0"/>
  <parent link="odom"/>
  <child link="base_footprint"/>
</joint> -->

 <joint name="base_joint" type="fixed">
    <origin xyz="0 0 0" rpy="0 0 0" />
    <parent link="base_footprint"/>
    <child link="base_link" />
    <axis xyz="0 0 0" rpy="0 0 0"/>
  </joint>

  <joint name="right_wheel_joint" type="continuous">  
    <parent link="base_link"/>
    <child link="right_wheel_link"/>
      <origin xyz="0.1 -0.19 0" rpy="1.5707 0 0.523599"/>

      <axis xyz="0 0 -1" rpy="0 0 0"/>
      <limit effort="10" velocity="100"/>
      <dynamics damping="1.0" friction="0.1"/>
  </joint>

  <joint name="back_wheel_joint" type="continuous">
    <parent link="base_link"/>
    <child link="back_wheel_link"/>
     <origin xyz="-0.21 0.0 0" rpy="1.5707 0 -1.5707"/>

      <axis xyz="0 0 -1" rpy="0 0 0"/>
      <limit effort="10" velocity="100"/>
      <dynamics damping="1.0" friction="0.1"/>

  </joint>

  <joint name="left_wheel_joint" type="continuous">
    <parent link="base_link"/>
    <child link="left_wheel_link"/>
     <origin xyz="0.1 0.19 0" rpy="-1.5707 0 -0.523599"/>

      <axis xyz="0 0 1" rpy="0 0 0"/>
      <limit effort="10" velocity="100"/>
      <dynamics damping="1.0" friction="0.1"/>

  </joint>

  <joint name="imu_joint" type="fixed">
    <parent link="base_link"/>
    <child link="Imu_link"/>
    <origin xyz="0.0 0.0 0.1" rpy="0.0 0.0 0.0"/>
  </joint> 
</robot>